<?xml version='1.0'?>
<sdf version='1.4'>
  <model name="l1_diff_robot">
    <static>false</static>
    <link name='base_link'>
            <pose>0 0 .1 0 0 0</pose>
            <inertial>
                <inertia>
                  <ixx>0.0833333</ixx>
                  <ixy>0</ixy>
                  <ixz>0</ixz>
                  <iyy>0.2833</iyy>
                  <iyz>0</iyz>
                  <izz>0.3333332</izz>
                </inertia>
                <mass>20.0</mass>
              </inertial>
            <collision name='collision'>
              <geometry>
                <box>
                  <size>.4 .2 .1</size>
                </box>
              </geometry>
            </collision>

            <visual name='visual'>
              <geometry>
                <box>
                  <size>.4 .2 .1</size>
                </box>
              </geometry>
            </visual>
          </link>

          <link name="caster">
            <pose> -0.15 0 0.05 0 0 0 </pose>
            <inertial>
                <inertia>
                  <ixx>0.004</ixx>
                  <ixy>0</ixy>
                  <ixz>0</ixz>
                  <iyy>0.004</iyy>
                  <iyz>0</iyz>
                  <izz>0.004</izz>
                </inertia>
                <mass>4.0</mass>
              </inertial>
            <collision name='collision'>
           <geometry>
               <sphere>
               <radius>.05</radius>
             </sphere>
           </geometry>

           <surface>
             <friction>
               <ode>
                 <mu>0</mu>
                 <mu2>0</mu2>
                 <slip1>1.0</slip1>
                 <slip2>1.0</slip2>
               </ode>
             </friction>
           </surface>
         </collision>

         <visual name='visual'>
           <geometry>
             <sphere>
               <radius>.05</radius>
             </sphere>
           </geometry>
         </visual>
     </link>

     <link name="left_wheel">
      <pose>0.1 0.13 0.1 0 1.5707 1.5707</pose>
      <inertial>
          <inertia>
            <ixx>0.002708332</ixx>
            <ixy>0</ixy>
            <ixz>0</ixz>
            <iyy>0.002708332</iyy>
            <iyz>0</iyz>
            <izz>0.005</izz>
          </inertia>
          <mass>1.0</mass>
        </inertial>
      <collision name="collision">
         <geometry>
           <cylinder>
             <radius>.1</radius>
             <length>.05</length>
           </cylinder>
         </geometry>
       </collision>
       <visual name="visual">
         <geometry>
           <cylinder>
             <radius>.1</radius>
             <length>.05</length>
           </cylinder>
         </geometry>
       </visual>
     </link>

     <link name="right_wheel">
        <pose>0.1 -0.13 0.1 0 1.5707 1.5707</pose>
        <inertial>
            <inertia>
              <ixx>0.002708332</ixx>
              <ixy>0</ixy>
              <ixz>0</ixz>
              <iyy>0.002708332</iyy>
              <iyz>0</iyz>
              <izz>0.005</izz>
            </inertia>
            <mass>1.0</mass>
          </inertial>
        <collision name="collision">
          <geometry>
            <cylinder>
              <radius>.1</radius>
              <length>.05</length>
            </cylinder>
          </geometry>
        </collision>
        <visual name="visual">
          <geometry>
            <cylinder>
              <radius>.1</radius>
              <length>.05</length>
            </cylinder>
          </geometry>
        </visual>
      </link>

      <joint type="revolute" name="left_wheel_hinge">
        <pose>0 0 -0.03 0 0 0</pose>
        <child>left_wheel</child>
        <parent>base_link</parent>
        <axis>
          <xyz>0 1 0</xyz>
        </axis>
      </joint>

      <joint type="revolute" name="right_wheel_hinge">
        <pose>0 0 0.03 0 0 0</pose>
        <child>right_wheel</child>
        <parent>base_link</parent>
        <axis>
          <xyz>0 1 0</xyz>
        </axis>
      </joint>

      <joint type="revolute" name="caster_hinge">
        <pose>0 0 0 0 0 0</pose>
        <child>caster</child>
        <parent>base_link</parent>
        <axis>
          <xyz>0 1 0</xyz>
        </axis>
      </joint>

      <plugin name="differential_drive_controller" filename="libgazebo_ros_diff_drive.so">
        <alwaysOn>true</alwaysOn>
        <updateRate>20</updateRate>
        <leftJoint>left_wheel_hinge</leftJoint>
        <rightJoint>right_wheel_hinge</rightJoint>
        <wheelSeparation>0.4</wheelSeparation>
        <wheelDiameter>0.1</wheelDiameter>
        <torque>2</torque>
        <commandTopic>cmd_vel</commandTopic>
        <robotBaseFrame>base_link</robotBaseFrame>
        <publishWheelJointState>true</publishWheelJointState>
        <legacyMode>true</legacyMode>
      </plugin>
  </model>
</sdf>
